<?xml version="1.0" ?>
<!-- =================================================================================== -->
<!-- |    This document was autogenerated by xacro from src/ulixarm_description/src/ulixarm_description/urdf/robot.urdf.xacro | -->
<!-- |    EDITING THIS FILE BY HAND IS NOT RECOMMENDED                                 | -->
<!-- =================================================================================== -->
<robot name="ulixarm">
  <!-- CONSTANTS -->
  <!-- LINKS -->
  <link name="manipulator_base_link">
    <visual>
      <origin xyz="0. 0. 0."/>
      <geometry>
        <mesh filename="package://ulixarm_description/meshes/visual/base_link.dae"/>
      </geometry>
    </visual>
    <collision>
      <origin xyz="0. 0. 0."/>
      <geometry>
        <mesh filename="package://ulixarm_description/meshes/collision/base_link.stl"/>
      </geometry>
    </collision>
    <!-- <inertial>
                <origin xyz="0. 0. 0."/>
                <mass value="0.0001"/>
                <inertia ixx="0.0001" ixy="0.0" ixz="0.0" iyy="0.0001" iyz="0.0" izz="0.0001"/>
            </inertial> -->
  </link>
  <link name="manipulator_link1">
    <visual>
      <origin xyz="0. 0. 0."/>
      <geometry>
        <mesh filename="package://ulixarm_description/meshes/visual/link1.dae"/>
      </geometry>
    </visual>
    <collision>
      <origin xyz="0. 0. 0."/>
      <geometry>
        <mesh filename="package://ulixarm_description/meshes/collision/link1.stl"/>
      </geometry>
    </collision>
    <inertial>
      <origin xyz="0. 0. 0.037"/>
      <mass value="0.480"/>
      <inertia ixx="0.0001" ixy="0.0" ixz="0.0" iyy="0.0001" iyz="0.0" izz="0.0001"/>
    </inertial>
  </link>
  <link name="manipulator_link2">
    <visual>
      <origin xyz="0. 0. 0."/>
      <geometry>
        <mesh filename="package://ulixarm_description/meshes/visual/link2.dae"/>
      </geometry>
    </visual>
    <collision>
      <origin xyz="0. 0. 0."/>
      <geometry>
        <mesh filename="package://ulixarm_description/meshes/collision/link2.stl"/>
      </geometry>
    </collision>
    <inertial>
      <origin xyz="0.197 0. -0.004"/>
      <mass value="0.690"/>
      <inertia ixx="0.0001" ixy="0.0" ixz="0.0" iyy="0.0001" iyz="0.0" izz="0.0001"/>
    </inertial>
  </link>
  <link name="manipulator_link3">
    <visual>
      <origin xyz="0. 0. 0."/>
      <geometry>
        <mesh filename="package://ulixarm_description/meshes/visual/link3.dae"/>
      </geometry>
    </visual>
    <collision>
      <origin xyz="0. 0. 0."/>
      <geometry>
        <mesh filename="package://ulixarm_description/meshes/collision/link3.stl"/>
      </geometry>
    </collision>
    <inertial>
      <origin xyz="0.197 0. -0.004"/>
      <mass value="0.680"/>
      <inertia ixx="0.0001" ixy="0.0" ixz="0.0" iyy="0.0001" iyz="0.0" izz="0.0001"/>
    </inertial>
  </link>
  <link name="manipulator_link4">
    <visual>
      <origin xyz="0. 0. 0."/>
      <geometry>
        <mesh filename="package://ulixarm_description/meshes/visual/link4.dae"/>
      </geometry>
    </visual>
    <collision>
      <origin xyz="0. 0. 0."/>
      <geometry>
        <mesh filename="package://ulixarm_description/meshes/collision/link4.stl"/>
      </geometry>
    </collision>
    <inertial>
      <origin xyz="0.022 0.0 0.018"/>
      <mass value="0.100"/>
      <inertia ixx="0.0001" ixy="0.0" ixz="0.0" iyy="0.0001" iyz="0.0" izz="0.0001"/>
    </inertial>
  </link>
  <link name="manipulator_link5">
    <visual>
      <origin xyz="0. 0. 0."/>
      <geometry>
        <mesh filename="package://ulixarm_description/meshes/visual/link5.dae"/>
      </geometry>
    </visual>
    <collision>
      <origin xyz="0. 0. 0."/>
      <geometry>
        <mesh filename="package://ulixarm_description/meshes/collision/link5.stl"/>
      </geometry>
    </collision>
    <inertial>
      <origin xyz="0.030 0.0 -0.023"/>
      <mass value="0.700"/>
      <inertia ixx="0.0001" ixy="0.0" ixz="0.0" iyy="0.0001" iyz="0.0" izz="0.0001"/>
    </inertial>
  </link>
  <link name="manipulator_link6">
    <inertial>
      <origin xyz="0. 0. 0."/>
      <mass value="0.001"/>
      <inertia ixx="0.0001" ixy="0.0" ixz="0.0" iyy="0.0001" iyz="0.0" izz="0.0001"/>
    </inertial>
  </link>
  <link name="manipulator_tool0">
    <inertial>
      <origin xyz="0. 0. 0."/>
      <mass value="0.001"/>
      <inertia ixx="0.0001" ixy="0.0" ixz="0.0" iyy="0.0001" iyz="0.0" izz="0.0001"/>
    </inertial>
  </link>
  <!-- JOINTS -->
  <joint name="joint1" type="revolute">
    <origin rpy="0. 0. 0." xyz="0. 0. 0.0533"/>
    <parent link="manipulator_base_link"/>
    <child link="manipulator_link1"/>
    <axis xyz="0 0 1"/>
    <limit effort="27.0" lower="-1.570796326795" upper="1.570796326795" velocity="8.0"/>
  </joint>
  <joint name="joint2" type="revolute">
    <origin rpy="3.14159265359 -1.570796326795 0." xyz="0.027175 0. 0.0425"/>
    <parent link="manipulator_link1"/>
    <child link="manipulator_link2"/>
    <axis xyz="0 0 1"/>
    <limit effort="27.0" lower="-1.570796326795" upper="1.570796326795" velocity="8.0"/>
  </joint>
  <joint name="joint3" type="revolute">
    <origin rpy="3.14159265359 0. 0." xyz="0.280 0. -0.0473"/>
    <parent link="manipulator_link2"/>
    <child link="manipulator_link3"/>
    <axis xyz="0 0 1"/>
    <limit effort="27.0" lower="-1.570796326795" upper="2.7925268" velocity="8.0"/>
  </joint>
  <joint name="joint4" type="revolute">
    <origin rpy="3.14159265359 0. -1.570796326795" xyz="0.260 0. -0.040"/>
    <parent link="manipulator_link3"/>
    <child link="manipulator_link4"/>
    <axis xyz="0 0 1"/>
    <limit effort="10.0" lower="-3.14159265359" upper="1.570796326795" velocity="30.0"/>
  </joint>
  <joint name="joint5" type="revolute">
    <origin rpy="1.570796326795 0. -1.570796326795" xyz="0.046 0. 0.031"/>
    <parent link="manipulator_link4"/>
    <child link="manipulator_link5"/>
    <axis xyz="0 0 -1"/>
    <limit effort="10.0" lower="-1.570796326795" upper="1.570796326795" velocity="30.0"/>
  </joint>
  <joint name="joint6" type="revolute">
    <origin rpy="1.570796326795 0. 1.570796326795" xyz="0.0825 0. -0.0235"/>
    <parent link="manipulator_link5"/>
    <child link="manipulator_link6"/>
    <axis xyz="0 0 1"/>
    <limit effort="10.0" lower="-1.570796326795" upper="1.570796326795" velocity="30.0"/>
  </joint>
  <joint name="joint_tool0" type="fixed">
    <parent link="manipulator_link6"/>
    <child link="manipulator_tool0"/>
  </joint>
  <!-- CONSTANTS -->
  <!-- LINKS -->
  <link name="gripper_base_link">
    <visual>
      <origin xyz="0. 0. 0."/>
      <geometry>
        <mesh filename="package://ulixarm_description/meshes/visual/gripper_base_link.dae"/>
      </geometry>
    </visual>
    <collision>
      <origin xyz="0. 0. 0."/>
      <geometry>
        <mesh filename="package://ulixarm_description/meshes/collision/gripper_base_link.stl"/>
      </geometry>
    </collision>
    <inertial>
      <origin xyz="0. 0. 0.052"/>
      <mass value="0.450"/>
      <inertia ixx="0.0001" ixy="0.0" ixz="0.0" iyy="0.0001" iyz="0.0" izz="0.0001"/>
    </inertial>
  </link>
  <link name="gripper_finger_right">
    <visual>
      <origin xyz="0. 0. 0."/>
      <geometry>
        <mesh filename="package://ulixarm_description/meshes/visual/finger_right.dae"/>
      </geometry>
    </visual>
    <collision>
      <origin xyz="0. 0. 0."/>
      <geometry>
        <mesh filename="package://ulixarm_description/meshes/collision/finger_right.stl"/>
      </geometry>
    </collision>
    <inertial>
      <origin xyz="0.008 0.002 -0.052"/>
      <mass value="0.075"/>
      <inertia ixx="0.0001" ixy="0.0" ixz="0.0" iyy="0.0001" iyz="0.0" izz="0.0001"/>
    </inertial>
  </link>
  <link name="gripper_finger_left">
    <visual>
      <origin xyz="0. 0. 0."/>
      <geometry>
        <mesh filename="package://ulixarm_description/meshes/visual/finger_right.dae"/>
      </geometry>
    </visual>
    <collision>
      <origin xyz="0. 0. 0."/>
      <geometry>
        <mesh filename="package://ulixarm_description/meshes/collision/finger_right.stl"/>
      </geometry>
    </collision>
    <inertial>
      <origin xyz="0.008 0.002 -0.052"/>
      <mass value="0.075"/>
      <inertia ixx="0.0001" ixy="0.0" ixz="0.0" iyy="0.0001" iyz="0.0" izz="0.0001"/>
    </inertial>
  </link>
  <!-- JOINTS -->
  <joint name="finger_right_joint" type="prismatic">
    <origin rpy="0. 0. 0." xyz="0. 0. 0.1289"/>
    <parent link="gripper_base_link"/>
    <child link="gripper_finger_right"/>
    <axis xyz="1 0 0"/>
    <limit effort="0.1" lower="0.0" upper="0.04" velocity="0.5"/>
  </joint>
  <joint name="finger_left_joint" type="prismatic">
    <origin rpy="0. 0. 3.14159265359" xyz="0. 0. 0.1289"/>
    <parent link="gripper_base_link"/>
    <child link="gripper_finger_left"/>
    <axis xyz="1 0 0"/>
    <mimic joint="finger_right_joint" multiplier="1" offset="0"/>
    <limit effort="0.1" lower="0.0" upper="0.04" velocity="0.5"/>
  </joint>
  <!-- Attach gripper base to the arm's end-effector link -->
  <joint name="manipulator_to_gripper" type="fixed">
    <parent link="manipulator_tool0"/>
    <child link="gripper_base_link"/>
    <origin rpy="0 0 0" xyz="0 0 0"/>
  </joint>
</robot>
