<?xml version="1.0" encoding="utf-8"?>
<robot name="ulixarm">
    
    <link name="world"></link>

    <link name="base_link">
        <visual>
            <origin xyz="0. 0. 0."/>
            <geometry>
                <mesh filename="package://ulixarm_description/meshes/visual/base.stl"/>
            </geometry>
        </visual>
        <collision>
            <origin xyz="0. 0. 0."/>
            <geometry>
                <mesh filename="package://ulixarm_description/meshes/collision/base.stl"/>
            </geometry>
        </collision>
    </link>

    <link name="link1">
        <visual>
            <origin xyz="0. 0. 0."/>
            <geometry>
                <mesh filename="package://ulixarm_description/meshes/visual/joint1.stl"/>
            </geometry>
        </visual>
        <collision>
            <origin xyz="0. 0. 0."/>
            <geometry>
                <mesh filename="package://ulixarm_description/meshes/collision/joint1.stl"/>
            </geometry>
        </collision>
    </link>

    <link name="link2">
        <visual>
            <origin xyz="0. 0. 0."/>
            <geometry>
                <mesh filename="package://ulixarm_description/meshes/visual/link1.stl"/>
            </geometry>
        </visual>
        <collision>
            <origin xyz="0. 0. 0."/>
            <geometry>
                <mesh filename="package://ulixarm_description/meshes/collision/link1.stl"/>
            </geometry>
        </collision>
    </link>

    <link name="link3">
        <visual>
            <origin xyz="0. 0. 0."/>
            <geometry>
                <mesh filename="package://ulixarm_description/meshes/visual/link2.stl"/>
            </geometry>
        </visual>
        <collision>
            <origin xyz="0. 0. 0."/>
            <geometry>
                <mesh filename="package://ulixarm_description/meshes/collision/link2.stl"/>
            </geometry>
        </collision>
    </link>

    <link name="link4">
        <visual>
            <origin xyz="0. 0. 0."/>
            <geometry>
                <mesh filename="package://ulixarm_description/meshes/visual/joint4.stl"/>
            </geometry>
        </visual>
        <collision>
            <origin xyz="0. 0. 0."/>
            <geometry>
                <mesh filename="package://ulixarm_description/meshes/collision/joint4.stl"/>
            </geometry>
        </collision>
    </link>

    <link name="link5">
        <visual>
            <origin xyz="0. 0. 0."/>
            <geometry>
                <mesh filename="package://ulixarm_description/meshes/visual/joint5.stl"/>
            </geometry>
        </visual>
        <collision>
            <origin xyz="0. 0. 0."/>
            <geometry>
                <mesh filename="package://ulixarm_description/meshes/collision/joint5.stl"/>
            </geometry>
        </collision>
    </link>

    <link name="tcp"></link>




    <joint name="joint0" type="fixed">
        <origin xyz="0. 0. 0." rpy="0. 0. 0."/>
        <parent link="world"/>
        <child link="base_link"/>
        <limit lower="0.0" upper="0.0" velocity="0.0" effort="0.0"/> 
    </joint>

    <joint name="joint1" type="revolute">
        <origin xyz="0. 0. 0.0533" rpy="0. 0. 0."/>
        <parent link="base_link"/>
        <child link="link1"/>
        <axis xyz="0 0 1"/>
        <limit lower="-1.57079632679" upper="1.57079632679" velocity="0.10" effort="0.5"/> 
    </joint>

    <joint name="joint2" type="revolute">
        <origin xyz="0.027175 0. 0.0425" rpy="3.14159265359 -1.57079632679 0."/>
        <parent link="link1"/>
        <child link="link2"/>
        <axis xyz="0 0 1"/>
        <limit lower="-1.57079632679" upper="1.57079632679" velocity="0.10" effort="0.5"/> 
    </joint>

    <joint name="joint3" type="revolute">
        <origin xyz="0.280 0. -0.0473" rpy="3.14159265359 0. 0."/>
        <parent link="link2"/>
        <child link="link3"/>
        <axis xyz="0 0 1"/>
        <limit lower="-1.57079632679" upper="2.7925268" velocity="0.10" effort="0.5"/> 
    </joint>

    <joint name="joint4" type="revolute">
        <origin xyz="0.260 0. -0.040" rpy="3.14159265359 0. -1.57079632679"/>
        <parent link="link3"/>
        <child link="link4"/>
        <axis xyz="0 0 1"/>
        <limit lower="-3.14159265359" upper="1.57079632679" velocity="0.10" effort="0.5"/> 
    </joint>

    <joint name="joint5" type="revolute">
        <origin xyz="0.046 0. 0.031" rpy="1.57079632679 0. -1.57079632679"/>
        <parent link="link4"/>
        <child link="link5"/>
        <axis xyz="0 0 1"/>
        <limit lower="-1.57079632679" upper="1.57079632679" velocity="0.10" effort="0.5"/> 
    </joint>

    <joint name="joint6" type="revolute">
        <origin xyz="0.0825 0. -0.0235" rpy="1.57079632679 0. 1.57079632679"/>
        <parent link="link5"/>
        <child link="tcp"/>
        <axis xyz="0 0 1"/>
        <limit lower="-1.57079632679" upper="1.57079632679" velocity="0.10" effort="0.5"/> 
    </joint>

</robot>